<mujoco model="bruce">
  <compiler angle="radian" meshdir="assets" autolimits="true"/>

  <option cone="elliptic" impratio="100" />

  <default>
    <default class="b2">
      <geom type="mesh"/>
      <joint damping="1" armature="0.1"/>
      <default class="visual">
        <geom contype="0" conaffinity="0" group="2"/>
      </default>
      <default class="collision">
        <geom group="3" mass="0" density="0"/>
      </default>
      <site size="0.001" rgba="0.5 0.5 0.5 0.3" group="4"/>
    </default>
  </default>

  <asset>
    <material name="transparent" rgba="1 1 1 0.01" />
    <material name="metal" rgba=".9 .95 .95 1" />
    <material name="black" rgba="0 0 0 1" />
    <material name="white" rgba="1 1 1 1" />
    <material name="gray" rgba="0.671705 0.692426 0.774270 1" />

    <mesh name="base_link" file="base_link.STL"/>
    <mesh name="Link_FL_Hip" file="Link_FL_Hip.STL"/>
    <mesh name="Link_FL_Thigh" file="Link_FL_Thigh.STL"/>
    <mesh name="Link_FL_Calf" file="Link_FL_Calf.STL"/>
    <mesh name="Link_FL_Foot" file="Link_FL_Foot.STL"/>
    <mesh name="Link_FR_Hip" file="Link_FR_Hip.STL"/>
    <mesh name="Link_FR_Thigh" file="Link_FR_Thigh.STL"/>
    <mesh name="Link_FR_Calf" file="Link_FR_Calf.STL"/>
    <mesh name="Link_FR_Foot" file="Link_FR_Foot.STL"/>
    <mesh name="Link_RL_Hip" file="Link_HL_Hip.STL"/>
    <mesh name="Link_RL_Thigh" file="Link_HL_Thigh.STL"/>
    <mesh name="Link_RL_Calf" file="Link_HL_Calf.STL"/>
    <mesh name="Link_RL_Foot" file="Link_HL_Foot.STL"/>
    <mesh name="Link_RR_Hip" file="Link_HR_Hip.STL"/>
    <mesh name="Link_RR_Thigh" file="Link_HR_Thigh.STL"/>
    <mesh name="Link_RR_Calf" file="Link_HR_Calf.STL"/>
    <mesh name="Link_RR_Foot" file="Link_HR_Foot.STL"/>
    <mesh name="Link_Imu" file="Link_Imu.STL"/>
  </asset>

  <worldbody>
    <geom type="mesh" rgba="0.75294 0.75294 0.75294 1" mesh="base_link"/>
    <geom pos="-0.0040103 0 0.114" quat="1 0 0 0" type="mesh" rgba="1 1 1 1" mesh="Link_Imu"/>
    
    <body name="Link_FL_Hip" pos="0.2635 0.0975 0.088">
      <inertial pos="0.071488 -0.01672 -4.7324e-05" quat="0.502992 0.502932 0.496921 0.49712" mass="2.9" diaginertia="0.00102348 0.00063315 0.000423265"/>
      <joint name="Joint_FL_Hip" pos="0 0 0" axis="1 0 0" range="-0.78 0.78" actuatorfrcrange="-200 200"/>
      <geom type="mesh" rgba="0.75294 0.75294 0.75294 1" mesh="Link_FL_Hip"/>
      <body name="Link_FL_Thigh" pos="0.07725 0.01475 0">
        <inertial pos="-0.044216 0.098313 -0.056091" quat="0.662933 -0.234795 -0.232765 0.671723" mass="5.58" diaginertia="0.0220954 0.0199915 0.00253099"/>
        <joint name="Joint_FL_Thigh" pos="0 0 0" axis="0 1 0" range="-1.22 2.61" actuatorfrcrange="-200 200"/>
        <geom type="mesh" rgba="0.75294 0.75294 0.75294 1" mesh="Link_FL_Thigh"/>
        <body name="Link_FL_Calf" pos="-0.17662 0.11925 -0.27282" quat="0.916975 0 -0.398944 0">
          <inertial pos="-0.0477228 2.11731e-05 -0.129525" quat="0.299555 0.640497 0.6406 0.299436" mass="1.26311" diaginertia="0.0389862 0.0262455 0.0130706"/>
          <joint name="Joint_FL_Calf" pos="0 0 0" axis="0 1 0" range="-1.3 0.52" actuatorfrcrange="-200 200"/>
          <geom type="mesh" rgba="0.752941 0.752941 0.752941 1" mesh="Link_FL_Calf"/>
          <geom pos="-0.0052369 -3.0756e-05 -0.33328" quat="0.916975 0 0.398944 0" type="mesh" rgba="0.752941 0.752941 0.752941 1" mesh="Link_FL_Foot"/>
        </body>
      </body>
    </body>
    <body name="Link_FR_Hip" pos="0.2635 -0.0975 0.088">
      <inertial pos="0.071488 0.01672 4.7324e-05" quat="0.496921 0.49712 0.502992 0.502932" mass="2.9" diaginertia="0.00102348 0.00063315 0.000423265"/>
      <joint name="Joint_FR_Hip" pos="0 0 0" axis="1 0 0" range="-0.78 0.78" actuatorfrcrange="-200 200"/>
      <geom type="mesh" rgba="0.75294 0.75294 0.75294 1" mesh="Link_FR_Hip"/>
      <body name="Link_FR_Thigh" pos="0.07725 -0.01475 0">
        <inertial pos="-0.044283 -0.09836 -0.056051" quat="0.670992 -0.232269 -0.2343 0.664021" mass="5.58" diaginertia="0.0221162 0.020003 0.002541"/>
        <joint name="Joint_FR_Thigh" pos="0 0 0" axis="0 1 0" range="-1.22 2.61" actuatorfrcrange="-200 200"/>
        <geom type="mesh" rgba="0.75294 0.75294 0.75294 1" mesh="Link_FR_Thigh"/>
        <body name="Link_FR_Calf" pos="-0.17662 -0.11925 -0.27282" quat="0.916975 0 -0.398944 0">
          <inertial pos="-0.0477228 2.11729e-05 -0.129525" quat="0.299555 0.640498 0.6406 0.299436" mass="1.26311" diaginertia="0.0389862 0.0262455 0.0130706"/>
          <joint name="Joint_FR_Calf" pos="0 0 0" axis="0 1 0" range="-1.3 0.52" actuatorfrcrange="-200 200"/>
          <geom type="mesh" rgba="0.752941 0.752941 0.752941 1" mesh="Link_FR_Calf"/>
          <geom pos="-0.0052369 -3.0756e-05 -0.33328" quat="0.916975 0 0.398944 0" type="mesh" rgba="0.752941 0.752941 0.752941 1" mesh="Link_FR_Foot"/>
        </body>
      </body>
    </body>
    <body name="Link_HL_Hip" pos="-0.2635 0.0975 0.088">
      <inertial pos="-0.071488 -0.01672 4.7324e-05" quat="0.49712 0.496921 0.502932 0.502992" mass="2.9" diaginertia="0.00102348 0.00063315 0.000423265"/>
      <joint name="Joint_HL_Hip" pos="0 0 0" axis="1 0 0" range="-0.78 0.78" actuatorfrcrange="-200 200"/>
      <geom type="mesh" rgba="0.75294 0.75294 0.75294 1" mesh="Link_HL_Hip"/>
      <body name="Link_HL_Thigh" pos="-0.07725 0.01475 0">
        <inertial pos="-0.044216 0.098313 -0.056091" quat="0.662933 -0.234795 -0.232765 0.671723" mass="5.58" diaginertia="0.0220954 0.0199915 0.00253099"/>
        <joint name="Joint_HL_Thigh" pos="0 0 0" axis="0 1 0" range="-1.22 2.61" actuatorfrcrange="-200 200"/>
        <geom type="mesh" rgba="0.75294 0.75294 0.75294 1" mesh="Link_HL_Thigh"/>
        <body name="Link_HL_Calf" pos="-0.17662 0.11925 -0.27282" quat="0.916975 0 -0.398944 0">
          <inertial pos="-0.0477228 2.11733e-05 -0.129525" quat="0.299555 0.640497 0.6406 0.299436" mass="1.26311" diaginertia="0.0389862 0.0262455 0.0130706"/>
          <joint name="Joint_HL_Calf" pos="0 0 0" axis="0 1 0" range="-1.3 0.52" actuatorfrcrange="-200 200"/>
          <geom type="mesh" rgba="0.752941 0.752941 0.752941 1" mesh="Link_HL_Calf"/>
          <geom pos="-0.0052369 -3.0756e-05 -0.33328" quat="0.916975 0 0.398944 0" type="mesh" rgba="0.752941 0.752941 0.752941 1" mesh="Link_HL_Foot"/>
        </body>
      </body>
    </body>
    <body name="Link_HR_Hip" pos="-0.2635 -0.0975 0.088">
      <inertial pos="-0.071488 0.01672 -4.7324e-05" quat="0.502932 0.502992 0.49712 0.496921" mass="2.9" diaginertia="0.00102348 0.00063315 0.000423265"/>
      <joint name="Joint_HR_Hip" pos="0 0 0" axis="1 0 0" range="-0.78 0.78" actuatorfrcrange="-200 200"/>
      <geom type="mesh" rgba="0.75294 0.75294 0.75294 1" mesh="Link_HR_Hip"/>
      <body name="Link_HR_Thigh" pos="-0.07725 -0.01475 0">
        <inertial pos="-0.044283 -0.09836 -0.056051" quat="0.670992 -0.232269 -0.2343 0.664021" mass="5.58" diaginertia="0.0221162 0.020003 0.002541"/>
        <joint name="Joint_HR_Thigh" pos="0 0 0" axis="0 1 0" range="-1.22 2.61" actuatorfrcrange="-200 200"/>
        <geom type="mesh" rgba="0.75294 0.75294 0.75294 1" mesh="Link_HR_Thigh"/>
        <body name="Link_HR_Calf" pos="-0.17662 -0.11925 -0.27282" quat="0.916975 0 -0.398944 0">
          <inertial pos="-0.0477228 2.11731e-05 -0.129529" quat="0.299551 0.640499 0.640602 0.299432" mass="1.26311" diaginertia="0.0389858 0.0262458 0.0130705"/>
          <joint name="Joint_HR_Calf" pos="0 0 0" axis="0 1 0" range="-1.3 0.52" actuatorfrcrange="-200 200"/>
          <geom type="mesh" rgba="0.75294 0.75294 0.75294 1" mesh="Link_HR_Calf"/>
          <geom pos="-0.0052369 -3.0756e-05 -0.33328" quat="0.916975 0 0.398944 0" type="mesh" rgba="0.75294 0.75294 0.75294 1" mesh="Link_HR_Foot"/>
        </body>
      </body>
    </body>
  </worldbody>

  <actuator>
    <motor class="abduction" name="FR_hip" joint="FR_hip_joint" />
    <motor class="hip" name="FR_thigh" joint="FR_thigh_joint" />
    <motor class="knee" name="FR_calf" joint="FR_calf_joint" />
    <motor class="abduction" name="FL_hip" joint="FL_hip_joint" />
    <motor class="hip" name="FL_thigh" joint="FL_thigh_joint" />
    <motor class="knee" name="FL_calf" joint="FL_calf_joint" />
    <motor class="abduction" name="RR_hip" joint="RR_hip_joint" />
    <motor class="hip" name="RR_thigh" joint="RR_thigh_joint" />
    <motor class="knee" name="RR_calf" joint="RR_calf_joint" />
    <motor class="abduction" name="RL_hip" joint="RL_hip_joint" />
    <motor class="hip" name="RL_thigh" joint="RL_thigh_joint" />
    <motor class="knee" name="RL_calf" joint="RL_calf_joint" />
  </actuator>

  <sensor>
    <jointpos name="FR_hip_pos" joint="FR_hip_joint" />
    <jointpos name="FR_thigh_pos" joint="FR_thigh_joint" />
    <jointpos name="FR_calf_pos" joint="FR_calf_joint" />
    <jointpos name="FL_hip_pos" joint="FL_hip_joint" />
    <jointpos name="FL_thigh_pos" joint="FL_thigh_joint" />
    <jointpos name="FL_calf_pos" joint="FL_calf_joint" />
    <jointpos name="RR_hip_pos" joint="RR_hip_joint" />
    <jointpos name="RR_thigh_pos" joint="RR_thigh_joint" />
    <jointpos name="RR_calf_pos" joint="RR_calf_joint" />
    <jointpos name="RL_hip_pos" joint="RL_hip_joint" />
    <jointpos name="RL_thigh_pos" joint="RL_thigh_joint" />
    <jointpos name="RL_calf_pos" joint="RL_calf_joint" />

    <jointvel name="FR_hip_vel" joint="FR_hip_joint" />
    <jointvel name="FR_thigh_vel" joint="FR_thigh_joint" />
    <jointvel name="FR_calf_vel" joint="FR_calf_joint" />
    <jointvel name="FL_hip_vel" joint="FL_hip_joint" />
    <jointvel name="FL_thigh_vel" joint="FL_thigh_joint" />
    <jointvel name="FL_calf_vel" joint="FL_calf_joint" />
    <jointvel name="RR_hip_vel" joint="RR_hip_joint" />
    <jointvel name="RR_thigh_vel" joint="RR_thigh_joint" />
    <jointvel name="RR_calf_vel" joint="RR_calf_joint" />
    <jointvel name="RL_hip_vel" joint="RL_hip_joint" />
    <jointvel name="RL_thigh_vel" joint="RL_thigh_joint" />
    <jointvel name="RL_calf_vel" joint="RL_calf_joint" />

    <jointactuatorfrc name="FR_hip_torque" joint="FR_hip_joint" noise="0.01" />
    <jointactuatorfrc name="FR_thigh_torque" joint="FR_thigh_joint" noise="0.01" />
    <jointactuatorfrc name="FR_calf_torque" joint="FR_calf_joint" noise="0.01" />
    <jointactuatorfrc name="FL_hip_torque" joint="FL_hip_joint" noise="0.01" />
    <jointactuatorfrc name="FL_thigh_torque" joint="FL_thigh_joint" noise="0.01" />
    <jointactuatorfrc name="FL_calf_torque" joint="FL_calf_joint" noise="0.01" />
    <jointactuatorfrc name="RR_hip_torque" joint="RR_hip_joint" noise="0.01" />
    <jointactuatorfrc name="RR_thigh_torque" joint="RR_thigh_joint" noise="0.01" />
    <jointactuatorfrc name="RR_calf_torque" joint="RR_calf_joint" noise="0.01" />
    <jointactuatorfrc name="RL_hip_torque" joint="RL_hip_joint" noise="0.01" />
    <jointactuatorfrc name="RL_thigh_torque" joint="RL_thigh_joint" noise="0.01" />
    <jointactuatorfrc name="RL_calf_torque" joint="RL_calf_joint" noise="0.01" />

    <framequat name="imu_quat" objtype="site" objname="imu" />
    <gyro name="imu_gyro" site="imu" />
    <accelerometer name="imu_acc" site="imu" />
    
    <framepos name="frame_pos" objtype="site" objname="imu" />
    <framelinvel name="frame_vel" objtype="site" objname="imu" />

    <touch name="FR_touch" site="FR_touch" />
    <touch name="FL_touch" site="FL_touch" />
    <touch name="RR_touch" site="RR_touch" />
    <touch name="RL_touch" site="RL_touch" />
  </sensor>

  <keyframe>
    <key name="home" qpos="0 0 0.1 1 0 0 0 0.3 1.5 -2.7 -0.15 1.2 -2.7 0.5 1.2 -2.7 -0.5 1.2 -2.7"
         ctrl="0 0 0 0 0 0 0 0 0 0 0 0" />
  </keyframe>

</mujoco>
